Workbook

Sheet 2013
A1: Cobre LME Prices 2013 US$/Ton | P1: US$ | Q1: Var (%) | R1: R$ | S1: Var (%)
A2: Janeiro 2013 | C2: Fevereiro 2013 | E2: Março 2013 | G2: Abril 2013 | I2: Maio 2013 | K2: Junho 2013 | O2: 41275 | P2: 8049.2455 | Q2: 0.0095984124 | R2: 16364.921 | S2: 0.0095984124
B3: Cash | D3: Cash | F3: Cash | H3: Cash | J3: Cash | L3: Cash | O3: 41306 | P3: 8070.475 | Q3: 0.0026374578 | R3: 15912.556 | S3: -0.027642381
C4: 1 | D4: 8160 | E4: 1 | F4: 7620.5 | G4: 1 | H4: Feriado | I4: 1 | J4: 6875 | K4: 3 | L4: 7330.5 | O4: 41334 | P4: 7662.4 | Q4: -0.050563938 | R4: 15212.929 | S4: -0.043966954
A5: 2 | B5: 8085 | C5: 4 | D5: 8226 | E5: 4 | F5: 7751 | G5: 2 | H5: 7434.5 | I5: 2 | J5: 6870.5 | K5: 4 | L5: 7337.5 | O5: 41365 | P5: 7203.3571 | Q5: -0.059908496 | R5: 14413.918 | S5: -0.052521859
A6: 3 | B6: 8140.5 | C6: 5 | D6: 8242.5 | E6: 5 | F6: 7720 | G6: 3 | H6: 7405.5 | I6: 3 | J6: 7122 | K6: 5 | L6: 7421.5 | O6: 41395 | P6: 7229.1429 | Q6: 0.0035796801 | R6: 14704.077 | S6: 0.020130469
A7: 4 | B7: 8026 | C7: 6 | D7: 8200 | E7: 6 | F7: 7699.5 | G7: 4 | H7: 7336.5 | I7: 6 | J7: Feriado | K7: 6 | L7: 7311 | O7: 41426 | P7: 7004.05 | Q7: -0.031136867 | R7: 15198.789 | S7: 0.033644542
A8: 7 | B8: 7995.5 | C8: 7 | D8: 8212 | E8: 7 | F8: 7671 | G8: 5 | H8: 7376 | I8: 7 | J8: 7240.5 | K8: 7 | L8: 7282 | O8: 41456 | P8: 6896.9773 | Q8: -0.015287259 | R8: 15536.683 | S8: 0.022231658
A9: 8 | B9: 8050.5 | C9: 8 | D9: 8215 | E9: 8 | F9: 7730 | G9: 8 | H9: 7457.5 | I9: 8 | J9: 7326 | K9: 10 | L9: 7120 | O9: 41487 | P9: 7182.2619 | Q9: 0.041363719 | R9: 16802.902 | S9: 0.081498669
A10: 9 | B10: 8059 | C10: 11 | D10: 8216 | E10: 11 | F10: 7667 | G10: 9 | H10: 7485.5 | I10: 9 | J10: 7311 | K10: 11 | L10: 7036 | O10: 41518 | P10: 7161.4286 | Q10: -0.0029006647 | R10: 16264.32 | S10: -0.032052874
A11: 10 | B11: 8117 | C11: 12 | D11: 8184.5 | E11: 12 | F11: 7815 | G11: 10 | H11: 7547 | I11: 10 | J11: 7390.5 | K11: 12 | L11: 7086 | O11: 41548 | P11: 7188.7826 | Q11: 0.0038196342 | R11: 15720.43 | S11: -0.033440722
A12: 11 | B12: 8071 | C12: 13 | D12: 8221 | E12: 13 | F12: 7777.5 | G12: 11 | H12: 7510 | I12: 13 | J12: 7350.5 | K12: 13 | L12: 7057.5 | O12: 41579 | P12: 7066.4048 | Q12: -0.017023445 | R12: 16235.772 | S12: 0.032781659
A13: 14 | B13: 8030 | C13: 14 | D13: 8197 | E13: 14 | F13: 7762 | G13: 12 | H13: 7510 | I13: 14 | J13: 7195 | K13: 14 | L13: 7045 | O13: 41609 | P13: 7202.95 | Q13: 0.019323156 | R13: 16911.086 | S13: 0.041594231
A14: 15 | B14: 7945 | C14: 15 | D14: 8198.5 | E14: 15 | F14: 7782 | G14: 15 | H14: 7120.5 | I14: 15 | J14: 7095.5 | K14: 17 | L14: 7020.5
A15: 16 | B15: 7910.5 | C15: 18 | D15: 8075.5 | E15: 18 | F15: 7555.5 | G15: 16 | H15: 7219 | I15: 16 | J15: 7095.5 | K15: 18 | L15: 6970.5
A16: 17 | B16: 7930 | C16: 19 | D16: 8070 | E16: 19 | F16: 7539 | G16: 17 | H16: 7067 | I16: 17 | J16: 7329.5 | K16: 19 | L16: 6972.5
A17: 18 | B17: 8053 | C17: 20 | D17: 8009.5 | E17: 20 | F17: 7574.5 | G17: 18 | H17: 6962.5 | I17: 20 | J17: 7276 | K17: 20 | L17: 6808
A18: 21 | B18: 8020.5 | C18: 21 | D18: 7847.5 | E18: 21 | F18: 7580 | G18: 19 | H18: 6975 | I18: 21 | J18: 7384 | K18: 21 | L18: 6777
A19: 22 | B19: 8068 | C19: 22 | D19: 7825 | E19: 22 | F19: 7618 | G19: 22 | H19: 6875.5 | I19: 22 | J19: 7480 | K19: 24 | L19: 6637.5
A20: 23 | B20: 8115.2 | C20: 25 | D20: 7865.5 | E20: 25 | F20: 7602 | G20: 23 | H20: 6811 | I20: 23 | J20: 7285.5 | K20: 25 | L20: 6726.5
A21: 24 | B21: 8036 | C21: 26 | D21: 7785 | E21: 26 | F21: 7631 | G21: 24 | H21: 6935.5 | I21: 24 | J21: 7240 | K21: 26 | L21: 6685.5
A22: 25 | B22: 8060 | C22: 27 | D22: 7831 | E22: 27 | F22: 7570 | G22: 25 | H22: 7035 | I22: 27 | J22: Feriado | K22: 27 | L22: 6705.5
A23: 28 | B23: 8015 | C23: 28 | D23: 7828 | E23: 28 | F23: 7582.5 | G23: 26 | H23: 7054.5 | I23: 28 | J23: 7257 | K23: 28 | L23: 6750.5
A24: 29 | B24: 8010.5 | G24: 29 | H24: 7079 | I24: 29 | J24: 7201.5
A25: 30 | B25: 8175.2 | G25: 30 | H25: 7073.5 | I25: 30 | J25: 7245.5
A26: 31 | B26: 8170 | I26: 31 | J26: 7241
A27: =B28/B69-1 -> #DIV/0! | C27: =D28/B28-1 -> 0.0026374578 | E27: =F28/D28-1 -> -0.050563938 | G27: =H28/F28-1 -> -0.059908496 | I27: =J28/H28-1 -> 0.0035796801 | K27: =L28/J28-1 -> -0.031136867
A28: MM | B28: =AVERAGE(B4:B26) -> 8049.2455 | C28: MM | D28: =AVERAGE(D4:D24) -> 8070.475 | E28: MM | F28: =AVERAGE(F4:F25) -> 7662.4 | G28: MM | H28: =AVERAGE(H4:H25) -> 7203.3571 | I28: MM | J28: =AVERAGE(J4:J26) -> 7229.1429 | K28: MM | L28: =AVERAGE(L4:L24) -> 7004.05
C29: =D23/B26-1 -> -0.041860465 | E29: =F23/D23-1 -> -0.031361778 | G29: =H25/F23-1 -> -0.067128256 | I29: =J26/H25-1 -> 0.023679932 | K29: =L23/J26-1 -> -0.067739263
A30: MM R$ | B30: =B28*A31 -> 16364.921 | C30: MM R$ | D30: =D28*C31 -> 15912.556 | E30: MM R$ | F30: =F28*E31 -> 15212.929 | G30: MM R$ | H30: =H28*G31 -> 14413.918 | I30: MM R$ | J30: =J28*I31 -> 14704.077 | K30: MM R$ | L30: =L28*K31 -> 15198.789
A31: 2.0331 | C31: 1.9717 | D31: =D30/B30-1 -> -0.027642381 | E31: 1.9854 | F31: =F30/D30-1 -> -0.043966954 | G31: 2.001 | H31: =H30/F30-1 -> -0.052521859 | I31: 2.034 | J31: =J30/H30-1 -> 0.020130469 | K31: 2.17 | L31: =L30/J30-1 -> 0.033644542
A32: Cobre LME Prices 2013 US$/Ton
A33: Julho 2013 | C33: Agosto 2013 | E33: Setembro 2013 | G33: Outubro 2013 | I33: Novembro 2013 | K33: Dezembro 2013
B34: Cash | D34: Cash | F34: Cash | H34: Cash | J34: Cash | L34: Cash
A35: 1 | B35: 6917 | C35: 1 | D35: 6999 | E35: 2 | F35: 7175.5 | G35: 1 | H35: 7219 | I35: 1 | J35: 7255.5 | K35: 2 | L35: 7008.5
A36: 2 | B36: 6980 | C36: 2 | D36: 7019 | E36: 3 | F36: 7183.5 | G36: 2 | H36: 7156 | I36: 4 | J36: 7180 | K36: 3 | L36: 6945
A37: 3 | B37: 6922 | C37: 5 | D37: 6950.5 | E37: 4 | F37: 7125.5 | G37: 3 | H37: 7216.5 | I37: 5 | J37: 7138.5 | K37: 4 | L37: 6975
A38: 4 | B38: 6920.5 | C38: 6 | D38: 7026.5 | E38: 5 | F38: 7103 | G38: 4 | H38: 7148 | I38: 6 | J38: 7200 | K38: 5 | L38: 7081
A39: 5 | B39: 6821 | C39: 7 | D39: 6892 | E39: 6 | F39: 7170.5 | G39: 7 | H39: 7171 | I39: 7 | J39: 7119 | K39: 6 | L39: 7113
A40: 8 | B40: 6765 | C40: 8 | D40: 7121.5 | E40: 9 | F40: 7191.5 | G40: 8 | H40: 7231.5 | I40: 8 | J40: 7125.5 | K40: 9 | L40: 7141
...

Sheet 2014
A1: Cobre LME Prices 2014 US$/Ton | O1: MÉDIAS
A2: Janeiro 2014 | C2: Fevereiro 2014 | E2: Março 2014 | G2: Abril 2014 | I2: Maio 2014 | K2: Junho 2014 | P2: US$ | Q2: Var (%) | R2: R$ | S2: Var (%)
B3: Cash | D3: Cash | F3: Cash | H3: Cash | J3: Cash | L3: Cash | O3: 41275 | P3: 8049.2455 | Q3: =P3/7962.58-1 -> 0.010884092 | R3: 16364.921 | S3: =R3/16546.24-1 -> -0.010958324
A4: 1 | B4: Feriado | C4: 3 | D4: 7095.5 | E4: 3 | F4: 7032.5 | G4: 1 | H4: 6632 | I4: 1 | J4: 6670.5 | K4: 2 | L4: 7003 | O4: 41306 | P4: 8070.475 | Q4: =P4/P3-1 -> 0.0026374578 | R4: 15912.556 | S4: =R4/R3-1 -> -0.027642381
A5: 2 | B5: 7439.5 | C5: 4 | D5: 7107 | E5: 4 | F5: 7035 | G5: 2 | H5: 6713 | I5: 2 | J5: 6699 | K5: 3 | L5: 6930 | O5: 41334 | P5: 7662.4 | Q5: =P5/P4-1 -> -0.050563938 | R5: 15212.929 | S5: =R5/R4-1 -> -0.043966954
A6: 3 | B6: 7335.5 | C6: 5 | D6: 7096 | E6: 5 | F6: 7102.5 | G6: 3 | H6: 6606 | I6: 6 | J6: 6740 | K6: 4 | L6: 6835 | O6: 41365 | P6: 7203.3571 | Q6: =P6/P5-1 -> -0.059908496 | R6: 14413.918 | S6: =R6/R5-1 -> -0.052521859
A7: 6 | B7: 7313.5 | C7: 6 | D7: 7109 | E7: 6 | F7: 7054.5 | G7: 4 | H7: 6677 | I7: 7 | J7: 6688 | K7: 5 | L7: 6800 | O7: 41395 | P7: 7229.1429 | Q7: =P7/P6-1 -> 0.0035796801 | R7: 14704.077 | S7: =R7/R6-1 -> 0.020130469
A8: 7 | B8: 7354 | C8: 7 | D8: 7200 | E8: 7 | F8: 6930.5 | G8: 7 | H8: 6610.5 | I8: 8 | J8: 6690.5 | K8: 6 | L8: 6660.5 | O8: 41426 | P8: 7004.05 | Q8: =P8/P7-1 -> -0.031136867 | R8: 15198.789 | S8: =R8/R7-1 -> 0.033644542
A9: 8 | B9: 7368 | C9: 10 | D9: 7190.5 | E9: 10 | F9: 6716 | G9: 8 | H9: 6652 | I9: 9 | J9: 6770 | K9: 9 | L9: 6667.5 | O9: 41456 | P9: 6896.9773 | Q9: =P9/P8-1 -> -0.015287259 | R9: 15536.683 | S9: =R9/R8-1 -> 0.022231658
A10: 9 | B10: 7282 | C10: 11 | D10: 7120 | E10: 11 | F10: 6720.5 | G10: 9 | H10: 6630.5 | I10: 12 | J10: 6930 | K10: 10 | L10: 6695.5 | O10: 41487 | P10: 7182.2619 | Q10: =P10/P9-1 -> 0.041363719 | R10: 16802.902 | S10: =R10/R9-1 -> 0.081498669
A11: 10 | B11: 7283.5 | C11: 12 | D11: 7174.5 | E11: 12 | F11: 6498 | G11: 10 | H11: 6637.5 | I11: 13 | J11: 6884.5 | K11: 11 | L11: 6689.5 | O11: 41518 | P11: 7161.4286 | Q11: =P11/P10-1 -> -0.0029006647 | R11: 16264.32 | S11: =R11/R10-1 -> -0.032052874
A12: 13 | B12: 7305.5 | C12: 13 | D12: 7157 | E12: 13 | F12: 6495 | G12: 11 | H12: 6686 | I12: 14 | J12: 6976.5 | K12: 12 | L12: 6725 | O12: 41548 | P12: 7188.7826 | Q12: =P12/P11-1 -> 0.0038196342 | R12: 15720.43 | S12: =R12/R11-1 -> -0.033440722
A13: 14 | B13: 7343 | C13: 14 | D13: 7175.5 | E13: 14 | F13: 6490 | G13: 14 | H13: 6645 | I13: 15 | J13: 6949 | K13: 13 | L13: 6671.5 | O13: 41579 | P13: 7066.4048 | Q13: =P13/P12-1 -> -0.017023445 | R13: 16235.772 | S13: =R13/R12-1 -> 0.032781659
A14: 15 | B14: 7309 | C14: 17 | D14: 7210 | E14: 17 | F14: 6550 | G14: 15 | H14: 6630 | I14: 16 | J14: 6950 | K14: 16 | L14: 6735 | O14: 41609 | P14: 7202.95 | Q14: =P14/P13-1 -> 0.019323156 | R14: 16911.086 | S14: =R14/R13-1 -> 0.041594231
A15: 16 | B15: 7345.5 | C15: 18 | D15: 7205 | E15: 18 | F15: 6471.5 | G15: 16 | H15: 6600 | I15: 19 | J15: 7009 | K15: 17 | L15: 6711 | O15: 41640 | P15: =B28 -> 7294.8864 | Q15: =P15/P14-1 -> 0.01276371 | R15: =B30 -> 17368.395 | S15: =R15/R14-1 -> 0.027041961
A16: 17 | B16: 7379.5 | C16: 19 | D16: 7220 | E16: 19 | F16: 6446 | G16: 17 | H16: 6631 | I16: 20 | J16: 6922.5 | K16: 18 | L16: 6739 | O16: 41671 | P16: =D28 -> 7152.15 | Q16: =P16/P15-1 -> -0.019566633 | R16: =D30 -> 17062.884 | S16: =R16/R15-1 -> -0.017590036
A17: 20 | B17: 7340 | C17: 20 | D17: 7185 | E17: 20 | F17: 6434.5 | G17: 18 | H17: Feriado | I17: 21 | J17: 6841 | K17: 19 | L17: 6730.5 | O17: 41699 | P17: =F28 -> 6667.8095 | Q17: =P17/P16-1 -> -0.067719564 | R17: =F30 -> 15507.991 | S17: =R17/R16-1 -> -0.0911272
A18: 21 | B18: 7332 | C18: 21 | D18: 7211.5 | E18: 21 | F18: 6539.5 | G18: 21 | H18: Feriado | I18: 22 | J18: 6945.5 | K18: 20 | L18: 6777.5 | O18: 41730 | P18: =H28 -> 6670.825 | Q18: =P18/P17-1 -> 0.0004522439 | R18: =H30 -> 14896.619 | S18: =R18/R17-1 -> -0.039423035
A19: 22 | B19: 7327 | C19: 24 | D19: 7130 | E19: 24 | F19: 6510 | G19: 22 | H19: 6628.5 | I19: 23 | J19: 6991 | K19: 23 | L19: 6901 | O19: 41760 | P19: =J28 -> 6883.875 | Q19: =P19/P18-1 -> 0.031937579 | R19: =J30 -> 15289.775 | S19: =R19/R18-1 -> 0.02639226
A20: 23 | B20: 7285 | C20: 25 | D20: 7115 | E20: 25 | F20: 6559.5 | G20: 23 | H20: 6645 | I20: 26 | J20: Feriado | K20: 24 | L20: 6898.5 | O20: 41791 | P20: =L28 -> 6806.0952 | Q20: =P20/P19-1 -> -0.011298834 | R20: =L30 -> 15206.178 | S20: =R20/R19-1 -> -0.0054674959
A21: 24 | B21: 7240 | C21: 26 | D21: 7149 | E21: 26 | F21: 6555 | G21: 24 | H21: 6731 | I21: 27 | J21: 7020 | K21: 25 | L21: 6890.5 | O21: 41821 | P21: =B82 -> 7104.8478 | Q21: =P21/P20-1 -> 0.043894859 | R21: =B84 -> 15807.576 | S21: =R21/R20-1 -> 0.03954958
A22: 27 | B22: 7235 | C22: 27 | D22: 7095 | E22: 27 | F22: 6581 | G22: 25 | H22: 6785.5 | I22: 28 | J22: 7035 | K22: 26 | L22: 6936.5 | O22: 41852 | P22: =D82 -> 7000.55 | Q22: =P22/P21-1 -> -0.014679811 | R22: =D84 -> 15880.048 | S22: =R22/R21-1 -> 0.0045846177
A23: 28 | B23: 7215 | C23: 28 | D23: 7097.5 | E23: 28 | F23: 6667 | G23: 28 | H23: 6782 | I23: 29 | J23: 6970 | K23: 27 | L23: 6976 | O23: 41883 | P23: =F82 -> 6872.2273 | Q23: =P23/P22-1 -> -0.018330378 | R23: =F84 -> 16046.651 | S23: =R23/R22-1 -> 0.010491345
A24: 29 | B24: 7209 | E24: 31 | F24: 6635.5 | G24: 29 | H24: 6770 | I24: 30 | J24: 6995.5 | K24: 30 | L24: 6955 | O24: 41913 | P24: =H82 -> 6739.1957 | Q24: =P24/P23-1 -> -0.019357861 | R24: =H84 -> 16515.747 | S24: =R24/R23-1 -> 0.029233272
A25: 30 | B25: 7155 | G25: 30 | H25: 6724 | O25: 41944 | P25: =J82 -> 6701.135 | Q25: =P25/P24-1 -> -0.005647655 | R25: =J84 -> 17154.906 | S25: =R25/R24-1 -> 0.038699965
A26: 31 | B26: 7091 | O26: 41974 | P26: =L82 -> 6422.9524 | Q26: =P26/P25-1 -> -0.041512762 | R26: =L84 -> 16968.798 | S26: =R26/R25-1 -> -0.010848658
A27: =B28/B88-1 -> 0.01276371 | C27: =D28/B28-1 -> -0.019566633 | E27: =F28/D28-1 -> -0.067719564 | G27: =H28/F28-1 -> 0.0004522439 | I27: =J28/H28-1 -> 0.031937579 | K27: =L28/J28-1 -> -0.011298834 | O27: Acumulado 2014 | Q27: =P26/P14-1 -> -0.10828863 | S27: =R26/R14-1 -> 0.0034126658
A28: MM | B28: =AVERAGE(B5:B26) -> 7294.8864 | C28: MM | D28: =AVERAGE(D4:D23) -> 7152.15 | E28: MM | F28: =AVERAGE(F4:F24) -> 6667.8095 | G28: MM | H28: =AVERAGE(H4:H25) -> 6670.825 | I28: MM | J28: =AVERAGE(J4:J24) -> 6883.875 | K28: MM | L28: =AVERAGE(L4:L24) -> 6806.0952
A29: =B26/B87-1 -> -0.041044019 | C29: =D19/B26-1 -> 0.0054999295 | E29: =F24/D23-1 -> -0.065093343 | G29: =H25/F24-1 -> 0.013337352 | I29: =J24/H25-1 -> 0.040377751 | K29: =L24/J24-1 -> -0.0057894361
A30: MM R$ | B30: =B28*A31 -> 17368.395 | C30: MM R$ | D30: =D28*C31 -> 17062.884 | E30: MM R$ | F30: =F28*E31 -> 15507.991 | G30: MM R$ | H30: =H28*G31 -> 14896.619 | I30: MM R$ | J30: =J28*I31 -> 15289.775 | K30: MM R$ | L30: =L28*K31 -> 15206.178
A31: 2.3809 | B31: =B30/B89-1 -> 0.027041961 | C31: 2.3857 | D31: =D30/B30-1 -> -0.017590036 | E31: 2.3258 | F31: =F30/D30-1 -> -0.0911272 | G31: 2.2331 | H31: =H30/F30-1 -> -0.039423035 | I31: 2.2211 | J31: =J30/H30-1 -> 0.02639226 | K31: 2.2342 | L31: =L30/J30-1 -> -0.0054674959
A32: Cobre LME Prices 2014 US$/Ton
A33: Julho 2014 | C33: Agosto 2014 | E33: Setembro 2014 | G33: Outubro 2014 | I33: Novembro 2014 | K33: Dezembro 2014
B34: Cash | D34: Cash | F34: Cash | H34: Cash | J34: Cash | L34: Cash
A51: Média | B51: #DIV/0! | C51: Média | D51: #DIV/0! | E51: Média | F51: #DIV/0! | G51: Média | H51: #DIV/0! | I51: Média | J51: #DIV/0! | K51: Média | L51: #DIV/0!
A52: MM | B52: #DIV/0! | C52: MM | D52: #DIV/0! | E52: MM | F52: #DIV/0! | G52: MM | H52: #DIV/0! | I52: MM | J52: #DIV/0! | K52: MM | L52: #DIV/0!
A53: #DIV/0! | C53: #DIV/0! | E53: #DIV/0! | G53: #DIV/0! | I53: #DIV/0! | K53: #DIV/0!
A54: MM R$ | B54: #DIV/0! | C54: MM R$ | D54: #DIV/0! | E54: MM R$ | F54: #DIV/0! | G54: MM R$ | H54: #DIV/0! | I54: MM R$ | J54: #DIV/0! | K54: MM R$ | L54: #DIV/0!
B55: #DIV/0! | D55: #DIV/0! | F55: #DIV/0! | H55: #DIV/0! | J55: #DIV/0! | L55: #DIV/0!
A56: Julho 2014 | C56: Agosto 2014 | E56: Setembro 2014 | G56: Outubro 2014 | I56: Novembro 2014 | K56: Dezembro 2014
...

Sheet 2015
A1: Cobre LME Prices 2015 US$/Ton | O1: MÉDIAS
A2: Janeiro 2015 | C2: Fevereiro 2015 | E2: Março 2015 | G2: Abril 2015 | I2: Maio 2015 | K2: Junho 2015 | P2: US$ | Q2: Var (%) | R2: R$ | S2: Var Mês (%) | T2: Acumulado/Ano
B3: Cash | D3: Cash | F3: Cash | H3: Cash | J3: Cash | L3: Cash | O3: 41275 | P3: 8049.2455 | Q3: =P3/7962.58-1 -> 0.010884092 | R3: 16364.921 | S3: =R3/16546.24-1 -> -0.010958324
A4: 2 | B4: 6309 | C4: 2 | D4: 5535.5 | E4: 2 | F4: 5896 | G4: 1 | H4: 6019.5 | I4: 1 | J4: 6362 | K4: 1 | L4: 5970.5 | O4: 41306 | P4: 8070.475 | Q4: =P4/P3-1 -> 0.0026374578 | R4: 15912.556 | S4: =R4/R3-1 -> -0.027642381
A5: 5 | B5: 6216 | C5: 3 | D5: 5695 | E5: 3 | F5: 5855 | G5: 2 | H5: 6001.5 | I5: 5 | J5: 6410 | K5: 2 | L5: 5998.5 | O5: 41334 | P5: 7662.4 | Q5: =P5/P4-1 -> -0.050563938 | R5: 15212.929 | S5: =R5/R4-1 -> -0.043966954
A6: 6 | B6: 6191 | C6: 4 | D6: 5708 | E6: 4 | F6: 5882 | G6: 3 | H6: feriado | I6: 6 | J6: 6400.5 | K6: 3 | L6: 5992 | O6: 41365 | P6: 7203.3571 | Q6: =P6/P5-1 -> -0.059908496 | R6: 14413.918 | S6: =R6/R5-1 -> -0.052521859
A7: 7 | B7: 6170 | C7: 5 | D7: 5595 | E7: 5 | F7: 5856 | G7: 6 | H7: feriado | I7: 7 | J7: 6437 | K7: 4 | L7: 5954 | O7: 41395 | P7: 7229.1429 | Q7: =P7/P6-1 -> 0.0035796801 | R7: 14704.077 | S7: =R7/R6-1 -> 0.020130469
A8: 8 | B8: 6230.5 | C8: 6 | D8: 5692 | E8: 6 | F8: 5826.5 | G8: 7 | H8: 6041 | I8: 8 | J8: 6396.5 | K8: 5 | L8: 5924.5 | O8: 41426 | P8: 7004.05 | Q8: =P8/P7-1 -> -0.031136867 | R8: 15198.789 | S8: =R8/R7-1 -> 0.033644542
A9: 9 | B9: 6151 | C9: 9 | D9: 5666 | E9: 9 | F9: 5800 | G9: 8 | H9: 6055 | I9: 11 | J9: 6363 | K9: 8 | L9: 5915 | O9: 41456 | P9: 6896.9773 | Q9: =P9/P8-1 -> -0.015287259 | R9: 15536.683 | S9: =R9/R8-1 -> 0.022231658
A10: 12 | B10: 6131 | C10: 10 | D10: 5591 | E10: 10 | F10: 5783.5 | G10: 9 | H10: 6050 | I10: 12 | J10: 6448 | K10: 9 | L10: 5989 | O10: 41487 | P10: 7182.2619 | Q10: =P10/P9-1 -> 0.041363719 | R10: 16802.902 | S10: =R10/R9-1 -> 0.081498669
A11: 13 | B11: 5915 | C11: 11 | D11: 5645.5 | E11: 11 | F11: 5786 | G11: 10 | H11: 6055 | I11: 13 | J11: 6416 | K11: 10 | L11: 6045.5 | O11: 41518 | P11: 7161.4286 | Q11: =P11/P10-1 -> -0.0029006647 | R11: 16264.32 | S11: =R11/R10-1 -> -0.032052874
A12: 14 | B12: 5627 | C12: 12 | D12: 5695 | E12: 12 | F12: 5865.5 | G12: 13 | H12: 6011.55 | I12: 14 | J12: 6399 | K12: 11 | L12: 5906 | O12: 41548 | P12: 7188.7826 | Q12: =P12/P11-1 -> 0.0038196342 | R12: 15720.43 | S12: =R12/R11-1 -> -0.033440722
A13: 15 | B13: 5719 | C13: 13 | D13: 5731 | E13: 13 | F13: 5860 | G13: 14 | H13: 5916.5 | I13: 15 | J13: 6356 | K13: 12 | L13: 5888.5 | O13: 41579 | P13: 7066.4048 | Q13: =P13/P12-1 -> -0.017023445 | R13: 16235.772 | S13: =R13/R12-1 -> 0.032781659
A14: 16 | B14: 5660 | C14: 16 | D14: 5712 | E14: 16 | F14: 5853 | G14: 15 | H14: 5920.5 | I14: 18 | J14: 6383 | K14: 15 | L14: 5760.5 | O14: 41609 | P14: 7202.95 | Q14: =P14/P13-1 -> 0.019323156 | R14: 16911.086 | S14: =R14/R13-1 -> 0.041594231
A15: 19 | B15: 5671 | C15: 17 | D15: 5665.5 | E15: 17 | F15: 5765 | G15: 16 | H15: 6054 | I15: 19 | J15: 6270 | K15: 16 | L15: 5752 | O15: 41640 | P15: 7294.8864 | Q15: 0.01276371 | R15: 17368.395 | S15: =R15/R14-1 -> 0.027041961 | T15: =R15/R14-1 -> 0.027041961
A16: 20 | B16: 5760.5 | C16: 18 | D16: 5690 | E16: 18 | F16: 5692.5 | G16: 17 | H16: 6081 | I16: 20 | J16: 6208 | K16: 17 | L16: 5749 | O16: 41671 | P16: 7152.15 | Q16: -0.019566633 | R16: 17062.884 | S16: =R16/R15-1 -> -0.017590036 | T16: =R16/R$14-1 -> 0.0089762565
A17: 21 | B17: 5630.5 | C17: 19 | D17: 5720 | E17: 19 | F17: 5835 | G17: 20 | H17: 6002 | I17: 21 | J17: 6240 | K17: 18 | L17: 5761 | O17: 41699 | P17: 6667.8095 | Q17: -0.067719564 | R17: 15507.991 | S17: =R17/R16-1 -> -0.0911272 | T17: =R17/R$14-1 -> -0.082968925
A18: 22 | B18: 5742 | C18: 20 | D18: 5707 | E18: 20 | F18: 5920 | G18: 21 | H18: 5975 | I18: 22 | J18: 6197.5 | K18: 19 | L18: 5663 | O18: 41730 | P18: 6670.825 | Q18: 0.0004522439 | R18: 14896.619 | S18: =R18/R17-1 -> -0.039423035 | T18: =R18/R$14-1 -> -0.11912107
A19: 23 | B19: 5581 | C19: 23 | D19: 5657 | E19: 23 | F19: 6093.5 | G19: 22 | H19: 5927 | I19: 26 | J19: 6134.5 | K19: 22 | L19: 5646 | O19: 41760 | P19: 6883.875 | Q19: 0.031937579 | R19: 15289.775 | S19: =R19/R18-1 -> 0.02639226 | T19: =R19/R$14-1 -> -0.095872687
A20: 26 | B20: 5490 | C20: 24 | D20: 5715 | E20: 24 | F20: 6128 | G20: 23 | H20: 5935 | I20: 27 | J20: 6085 | K20: 23 | L20: 5725 | O20: 41791 | P20: 6806.0952 | Q20: -0.011298834 | R20: 15206.178 | S20: =R20/R19-1 -> -0.0054674959 | T20: =R20/R$14-1 -> -0.100816
A21: 27 | B21: 5557 | C21: 25 | D21: 5805 | E21: 25 | F21: 6134.5 | G21: 24 | H21: 6025.5 | I21: 28 | J21: 6117 | K21: 24 | L21: 5765 | O21: 41821 | P21: 7104.8478 | Q21: 0.043894859 | R21: 15807.576 | S21: =R21/R20-1 -> 0.03954958 | T21: =R21/R$14-1 -> -0.06525365
A22: 28 | B22: 5485.5 | C22: 26 | D22: 5935.5 | E22: 26 | F22: 6230 | G22: 27 | H22: 6061 | I22: 29 | J22: 6088.5 | K22: 25 | L22: 5715.5 | O22: 41852 | P22: 7000.55 | Q22: -0.014679811 | R22: 15880.048 | S22: =R22/R21-1 -> 0.0045846177 | T22: =R22/R$14-1 -> -0.060968195
A23: 29 | B23: 5390.5 | C23: 27 | D23: 5880.5 | E23: 27 | F23: 6146 | G23: 28 | H23: 6090.5 | K23: 26 | L23: 5731 | O23: 41883 | P23: 6872.2273 | Q23: -0.018330378 | R23: 16046.651 | S23: =R23/R22-1 -> 0.010491345 | T23: =R23/R$14-1 -> -0.051116488
A24: 30 | B24: 5505 | E24: 30 | F24: 6110 | G24: 29 | H24: 6103 | K24: 29 | L24: 5767 | O24: 41913 | P24: 6739.1957 | Q24: -0.019357861 | R24: 16515.747 | S24: =R24/R23-1 -> 0.029233272 | T24: =R24/R$14-1 -> -0.023377518
E25: 31 | F25: 6050.5 | G25: 30 | H25: 6245 | K25: 30 | L25: 5721 | O25: 41944 | P25: 6701.135 | Q25: -0.005647655 | R25: 17154.906 | S25: =R25/R24-1 -> 0.038699965 | T25: =R25/R$14-1 -> 0.014417737
O26: 41974 | P26: ='2014'!L82 -> 6422.9524 | Q26: =P26/P25-1 -> -0.041512762 | R26: ='2014'!L84 -> 16968.798 | S26: =R26/R25-1 -> -0.010848658 | T26: =R26/R$14-1 -> 0.0034126658
A27: =B28/'2014'!L82-1 -> -0.098362458 | C27: =D28/B28-1 -> -0.015385479 | E27: =F28/D28-1 -> 0.038201841 | G27: =H28/F28-1 -> 0.018340285 | I27: =J28/H28-1 -> 0.04514038 | K27: =L28/J28-1 -> -0.074118534 | O27: 42005 | P27: =B28 -> 5791.175 | Q27: =P27/P26-1 -> -0.098362458 | R27: =B30 -> 15271.908 | S27: =R27/R26-1 -> -0.10000062 | T27: =R27/R26-1 -> -0.10000062
A28: MM | B28: =AVERAGE(B5:B26) -> 5791.175 | C28: MM | D28: =AVERAGE(D4:D23) -> 5702.075 | E28: MM | F28: =AVERAGE(F4:F24) -> 5919.9048 | G28: MM | H28: =AVERAGE(H4:H25) -> 6028.4775 | I28: MM | J28: =AVERAGE(J4:J23) -> 6300.6053 | K28: MM | L28: =AVERAGE(L4:L25) -> 5833.6136 | O28: 42036 | P28: =D28 -> 5702.075 | Q28: =P28/P27-1 -> -0.015385479 | R28: =D30 -> 16059.837 | S28: =R28/R27-1 -> 0.051593399 | T28: =R28/R26-1 -> -0.053566592
O29: 42064 | P29: =F28 -> 5919.9048 | Q29: =P29/P28-1 -> 0.038201841 | R29: =F30 -> 18601.525 | S29: =R29/R28-1 -> 0.15826359 | T29: =R29/R26-1 -> 0.096219358
A30: MM R$ | B30: =B28*A31 -> 15271.908 | C30: MM R$ | D30: =D28*C31 -> 16059.837 | E30: MM R$ | F30: =F28*E31 -> 18601.525 | G30: MM R$ | H30: =H28*G31 -> 18401.928 | I30: MM R$ | J30: =J28*I31 -> 19242.048 | K30: MM R$ | L30: =L28*K31 -> 18168.79 | O30: 42095 | P30: =H28 -> 6028.4775 | Q30: =P30/P29-1 -> 0.018340285 | R30: =H30 -> 18401.928 | S30: =R30/R29-1 -> -0.010730151 | T30: =R30/R26-1 -> 0.084456759
A31: 2.6371 | B31: =B30/'2014'!L84-1 -> -0.10000062 | C31: 2.81649 | D31: =D30/B30-1 -> 0.051593399 | E31: 3.1422 | F31: =F30/D30-1 -> 0.15826359 | G31: 3.0525 | H31: =H30/F30-1 -> -0.010730151 | I31: 3.054 | J31: =J30/H30-1 -> 0.045653962 | K31: 3.1145 | L31: =L30/J30-1 -> -0.055776744 | O31: 42125 | P31: =J28 -> 6300.6053 | Q31: =P31/P30-1 -> 0.04514038 | R31: =J30 -> 19242.048 | S31: =R31/R30-1 -> 0.045653962 | T31: =R31/R26-1 -> 0.13396651
A32: Cobre LME Prices 2015 US$/Ton | O32: 42156 | P32: =L28 -> 5833.6136 | Q32: =P32/P31-1 -> -0.074118534 | R32: =L30 -> 18168.79 | S32: =R32/R31-1 -> -0.055776744 | T32: =R32/R26-1 -> 0.070717548
A33: Julho 2014 | C33: Agosto 2014 | E33: Setembro 2014 | G33: Outubro 2014 | I33: Novembro 2014 | K33: Dezembro 2014 | O33: 42186 | T33: =R33/R27-1 -> -1
B34: Cash | D34: Cash | F34: Cash | H34: Cash | J34: Cash | L34: Cash | O34: 42217 | T34: =R34/R28-1 -> -1
O35: 42248 | T35: =R35/R29-1 -> -1
O36: 42278 | T36: =R36/R30-1 -> -1
O37: 42309 | T37: =R37/R31-1 -> -1
O38: 42339 | T38: =R38/R32-1 -> -1
O39: 42370 | T39: =R39/R33-1 -> #DIV/0!
O40: 42401 | T40: =R40/R34-1 -> #DIV/0!
...

Sheet 2016
A1: Cobre LME Prices 2016 US$/Ton | O1: MÉDIAS
A2: Janeiro 2016 | C2: Fevereiro 2016 | E2: Março 2016 | G2: Abril 2016 | I2: Maio 2016 | K2: Junho 2016 | P2: US$ | Q2: Var (%) | R2: R$ | S2: Var Mês (%) | T2: Acumulado/Ano
B3: Cash | D3: Cash | F3: Cash | H3: Cash | J3: Cash | L3: Cash | O3: 41275 | P3: 8049.2455 | Q3: 0.010884092 | R3: 16364.921 | S3: -0.010958324
A4: 4 | B4: 4645 | C4: 1 | D4: 4534 | E4: 1 | F4: 4726 | G4: 1 | H4: 4880 | I4: 3 | J4: 4960 | K4: 1 | L4: 4601 | O4: 41306 | P4: 8070.475 | Q4: 0.0026374578 | R4: 15912.556 | S4: -0.027642381
A5: 5 | B5: 4647 | C5: 2 | D5: 4605.5 | E5: 2 | F5: 4780 | G5: 4 | H5: 4816 | I5: 4 | J5: 4892 | K5: 2 | L5: 4600 | O5: 41334 | P5: 7662.4 | Q5: -0.050563938 | R5: 15212.929 | S5: -0.043966954
A6: 6 | B6: 4600 | C6: 3 | D6: 4578.5 | E6: 3 | F6: 4830 | G6: 5 | H6: 4776 | I6: 5 | J6: 4826 | K6: 3 | L6: 4688 | O6: 41365 | P6: 7203.3571 | Q6: -0.059908496 | R6: 14413.918 | S6: -0.052521859
A7: 7 | B7: 4514 | C7: 4 | D7: 4685 | E7: 4 | F7: 4918 | G7: 6 | H7: 4775 | I7: 6 | J7: 4810 | K7: 6 | L7: 4706 | O7: 41395 | P7: 7229.1429 | Q7: 0.0035796801 | R7: 14704.077 | S7: 0.020130469
A8: 8 | B8: 4486.5 | C8: 5 | D8: 4669 | E8: 7 | F8: 5000 | G8: 7 | H8: 4715 | I8: 9 | J8: 4739.5 | K8: 7 | L8: 4589 | O8: 41426 | P8: 7004.05 | Q8: -0.031136867 | R8: 15198.789 | S8: 0.033644542
A9: 11 | B9: 4402.5 | C9: 8 | D9: 4572.5 | E9: 8 | F9: 4980.5 | G9: 8 | H9: 4654 | I9: 10 | J9: 4710 | K9: 8 | L9: 4590.5 | O9: 41456 | P9: 6896.9773 | Q9: -0.015287259 | R9: 15536.683 | S9: 0.022231658
A10: 12 | B10: 4355 | C10: 9 | D10: 4530.5 | E10: 9 | F10: 4935.5 | G10: 11 | H10: 4645 | I10: 11 | J10: 4748 | K10: 9 | L10: 4546 | O10: 41487 | P10: 7182.2619 | Q10: 0.041363719 | R10: 16802.902 | S10: 0.081498669
A11: 13 | B11: 4380 | C11: 10 | D11: 4507 | E11: 10 | F11: 4920.5 | G11: 12 | H11: 4715.5 | I11: 12 | J11: 4744 | K11: 10 | L11: 4504 | O11: 41518 | P11: 7161.4286 | Q11: -0.0029006647 | R11: 16264.32 | S11: -0.032052874
A12: 14 | B12: 4365.5 | C12: 11 | D12: 4474 | E12: 11 | F12: 4941 | G12: 13 | H12: 4838 | I12: 13 | J12: 4660 | K12: 13 | L12: 4515 | O12: 41548 | P12: 7188.7826 | Q12: 0.0038196342 | R12: 15720.43 | S12: -0.033440722
A13: 15 | B13: 4310.5 | C13: 12 | D13: 4488.5 | E13: 14 | F13: 4994 | G13: 14 | H13: 4830.5 | I13: 16 | J13: 4640.5 | K13: 14 | L13: 4610.5 | O13: 41579 | P13: 7066.4048 | Q13: -0.017023445 | R13: 16235.772 | S13: 0.032781659
A14: 18 | B14: 4360 | C14: 15 | D14: 4562 | E14: 15 | F14: 4920 | G14: 15 | H14: 4813.5 | I14: 17 | J14: 4634 | K14: 15 | L14: 4632 | O14: 41609 | P14: 7202.95 | Q14: 0.019323156 | R14: 16911.086 | S14: 0.041594231
A15: 19 | B15: 4440.5 | C15: 16 | D15: 4583.5 | E15: 16 | F15: 4945 | G15: 18 | H15: 4798 | I15: 18 | J15: 4600.5 | K15: 16 | L15: 4524.5 | O15: 41640 | P15: 7294.8864 | Q15: 0.01276371 | R15: 17368.395 | S15: 0.027041961 | T15: 0.027041961
A16: 20 | B16: 4347 | C16: 17 | D16: 4562 | E16: 17 | F16: 5029 | G16: 19 | H16: 4812 | I16: 19 | J16: 4596 | K16: 17 | L16: 4521.5 | O16: 41671 | P16: 7152.15 | Q16: -0.019566633 | R16: 17062.884 | S16: -0.017590036 | T16: 0.0089762565
A17: 21 | B17: 4376 | C17: 18 | D17: 4577 | E17: 18 | F17: 5103 | G17: 20 | H17: 4938.5 | I17: 20 | J17: 4630.5 | K17: 20 | L17: 4585 | O17: 41699 | P17: 6667.8095 | Q17: -0.067719564 | R17: 15507.991 | S17: -0.0911272 | T17: -0.082968925
A18: 22 | B18: 4468 | C18: 19 | D18: 4590 | E18: 21 | F18: 5079.5 | G18: 21 | H18: 5025.5 | I18: 23 | J18: 4572 | K18: 21 | L18: 4587 | O18: 41730 | P18: 6670.825 | Q18: 0.0004522439 | R18: 14896.619 | S18: -0.039423035 | T18: -0.11912107
A19: 25 | B19: 4454 | C19: 22 | D19: 4696 | E19: 22 | F19: 5070 | G19: 22 | H19: 5015.5 | I19: 24 | J19: 4637 | K19: 22 | L19: 4687.5 | O19: 41760 | P19: 6883.875 | Q19: 0.031937579 | R19: 15289.775 | S19: 0.02639226 | T19: -0.095872687
A20: 26 | B20: 4501 | C20: 23 | D20: 4663.5 | E20: 23 | F20: 5060.5 | G20: 25 | H20: 5005.5 | I20: 25 | J20: 4636 | K20: 23 | L20: 4747 | O20: 41791 | P20: 6806.0952 | Q20: -0.011298834 | R20: 15206.178 | S20: -0.0054674959 | T20: -0.100816
A21: 27 | B21: 4507.5 | C21: 24 | D21: 4585.5 | E21: 24 | F21: 4931 | G21: 26 | H21: 4935.5 | I21: 26 | J21: 4705.5 | K21: 24 | L21: 4663 | O21: 41821 | P21: 7104.8478 | Q21: 0.043894859 | R21: 15807.576 | S21: 0.03954958 | T21: -0.06525365
A22: 28 | B22: 4553.5 | C22: 25 | D22: 4655 | E22: 29 | F22: 4939.5 | G22: 27 | H22: 4932 | I22: 27 | J22: 4725.5 | K22: 27 | L22: 4692 | O22: 41852 | P22: 7000.55 | Q22: -0.014679811 | R22: 15880.048 | S22: 0.0045846177 | T22: -0.060968195
A23: 29 | B23: 4541.5 | C23: 26 | D23: 4681 | E23: 30 | F23: 4940 | G23: 28 | H23: 4912.5 | I23: 31 | J23: 4700 | K23: 28 | L23: 4777.5 | O23: 41883 | P23: 6872.2273 | Q23: -0.018330378 | R23: 16046.651 | S23: 0.010491345 | T23: -0.051116488
C24: 29 | D24: 4705 | E24: 31 | F24: 4855.5 | G24: 29 | H24: 5045 | K24: 29 | L24: 4780 | O24: 41913 | P24: 6739.1957 | Q24: -0.019357861 | R24: 16515.747 | S24: 0.029233272 | T24: -0.023377518
K25: 30 | L25: 4827 | O25: 41944 | P25: 6701.135 | Q25: -0.005647655 | R25: 17154.906 | S25: 0.038699965 | T25: 0.014417737
A26: =B27/'2015'!L82-1 -> -0.035914884 | C26: =D27/B27-1 -> 0.029740898 | E26: =F27/D27-1 -> 0.076612611 | G26: =H27/F27-1 -> -0.019442052 | I26: =J27/H27-1 -> -0.02947776 | K26: =L27/J27-1 -> -0.01554009 | O26: 41974 | P26: 6422.9524 | Q26: -0.041512762 | R26: 16968.798 | S26: -0.010848658 | T26: 0.0034126658
A27: MM | B27: =AVERAGE(B4:B25) -> 4462.75 | C27: MM | D27: =AVERAGE(D4:D24) -> 4595.4762 | E27: MM | F27: =AVERAGE(F4:F24) -> 4947.5476 | G27: MM | H27: =AVERAGE(H4:H25) -> 4851.3571 | I27: MM | J27: =AVERAGE(J4:J23) -> 4708.35 | K27: MM | L27: =AVERAGE(L4:L25) -> 4635.1818 | O27: 42005 | P27: 5791.175 | Q27: -0.098362458 | R27: 15271.908 | S27: -0.10000062 | T27: -0.10000062
A28: MM R$ | B28: =B27*A29 -> 18027.279 | C28: MM R$ | D28: =D27*C29 -> 18233.011 | E28: MM R$ | F28: =F27*E29 -> 18272.778 | G28: MM R$ | H28: =H27*G29 -> 17299.454 | I28: MM R$ | J28: =J27*I29 -> 16669.913 | K28: MM R$ | L28: =L27*K29 -> 15898.674 | O28: 42036 | P28: 5702.075 | Q28: -0.015385479 | R28: 16059.837 | S28: 0.051593399 | T28: -0.053566592
A29: 4.0395 | B29: =B28/'2015'!L84-1 -> 0.0055570307 | C29: 3.9676 | D29: =D28/B28-1 -> 0.0114123 | E29: 3.6933 | F29: =F28/D28-1 -> 0.002181005 | G29: 3.5659 | H29: =H28/F28-1 -> -0.053266296 | I29: 3.5405 | J29: =J28/H28-1 -> -0.036390816 | K29: 3.43 | L29: =L28/J28-1 -> -0.04626536 | O29: 42064 | P29: 5919.9048 | Q29: 0.038201841 | R29: 18601.525 | S29: 0.15826359 | T29: 0.096219358
A30: Cobre LME Prices 2016 US$/Ton | O30: 42095 | P30: 6028.4775 | Q30: 0.018340285 | R30: 18401.928 | S30: -0.010730151 | T30: 0.084456759
A31: Julho 2016 | C31: Agosto 2016 | E31: Setembro 2016 | G31: Outubro 2016 | I31: Novembro 2016 | K31: Dezembro 2016 | O31: 42125 | P31: 6300.6053 | Q31: 0.04514038 | R31: 19242.048 | S31: 0.045653962 | T31: 0.13396651
B32: Cash | D32: Cash | F32: Cash | H32: Cash | J32: Cash | L32: Cash | O32: 42156 | P32: 5833.6136 | Q32: -0.074118534 | R32: 18168.79 | S32: -0.055776744 | T32: 0.070717548
O33: 42186 | T33: -1
O34: 42217 | T34: -1
O35: 42248 | T35: -1
O36: 42278 | T36: -1
O37: 42309 | T37: -1
O38: 42339 | T38: -1
O39: 42370 | T39: #DIV/0!
O40: 42401 | T40: #DIV/0!
...

Sheet 2017
A1: Cobre LME Prices 2017 US$/Ton | O1: MÉDIAS
A2: Janeiro 2017 | C2: Fevereiro 2017 | E2: Março 2017 | G2: Abril 2017 | I2: Maio 2017 | K2: Junho 2017 | P2: US$ | Q2: Var (%) | R2: R$ | S2: Var Mês (%) | T2: Acumulado/Ano
B3: Cash | D3: Cash | F3: Cash | H3: Cash | J3: Cash | L3: Cash | O3: 41275 | P3: 8049.2455 | Q3: 0.010884092 | R3: 16364.921 | S3: -0.010958324
A4: 3 | B4: 5574 | C4: 1 | D4: 5931 | E4: 1 | F4: 6040 | G4: 3 | H4: 5817 | I4: 2 | J4: 5746.5 | K4: 1 | L4: 5636.5 | O4: 41306 | P4: 8070.475 | Q4: 0.0026374578 | R4: 15912.556 | S4: -0.027642381
A5: 4 | B5: 5500.5 | C5: 2 | D5: 5903 | E5: 2 | F5: 5994 | G5: 4 | H5: 5724.5 | I5: 3 | J5: 5636.5 | K5: 2 | L5: 5559.5 | O5: 41334 | P5: 7662.4 | Q5: -0.050563938 | R5: 15212.929 | S5: -0.043966954
A6: 5 | B6: 5611 | C6: 3 | D6: 5836 | E6: 3 | F6: 5910 | G6: 5 | H6: 5808.5 | I6: 4 | J6: 5543 | K6: 5 | L6: 5586.5 | O6: 41365 | P6: 7203.3571 | Q6: -0.059908496 | R6: 14413.918 | S6: -0.052521859
A7: 6 | B7: 5546.5 | C7: 6 | D7: 5786 | E7: 6 | F7: 5856 | G7: 6 | H7: 5870.5 | I7: 5 | J7: 5530.5 | K7: 6 | L7: 5540.5 | O7: 41395 | P7: 7229.1429 | Q7: 0.0035796801 | R7: 14704.077 | S7: 0.020130469
A8: 9 | B8: 5551.5 | C8: 7 | D8: 5802 | E8: 7 | F8: 5807 | G8: 7 | H8: 5770 | I8: 8 | J8: 5466 | K8: 7 | L8: 5575.5 | O8: 41426 | P8: 7004.05 | Q8: -0.031136867 | R8: 15198.789 | S8: 0.033644542
A9: 10 | B9: 5642 | C9: 8 | D9: 5865 | E9: 8 | F9: 5782 | G9: 10 | H9: 5731 | I9: 9 | J9: 5496 | K9: 8 | L9: 5647.5 | O9: 41456 | P9: 6896.9773 | Q9: -0.015287259 | R9: 15536.683 | S9: 0.022231658
A10: 11 | B10: 5709.5 | C10: 9 | D10: 5863 | E10: 9 | F10: 5655 | G10: 11 | H10: 5746 | I10: 10 | J10: 5512 | K10: 9 | L10: 5739 | O10: 41487 | P10: 7182.2619 | Q10: 0.041363719 | R10: 16802.902 | S10: 0.081498669
A11: 12 | B11: 5752.5 | C11: 10 | D11: 5872 | E11: 10 | F11: 5714.5 | G11: 12 | H11: 5685 | I11: 11 | J11: 5580.5 | K11: 12 | L11: 5752 | O11: 41518 | P11: 7161.4286 | Q11: -0.0029006647 | R11: 16264.32 | S11: -0.032052874
A12: 13 | B12: 5797 | C12: 13 | D12: 6111 | E12: 13 | F12: 5794 | G12: 13 | H12: 5655 | I12: 12 | J12: 5520 | K12: 13 | L12: 5659 | O12: 41548 | P12: 7188.7826 | Q12: 0.0038196342 | R12: 15720.43 | S12: -0.033440722
A13: 16 | B13: 5857 | C13: 14 | D13: 6145 | E13: 14 | F13: 5747 | G13: 18 | H13: 5620.5 | I13: 15 | J13: 5586 | K13: 14 | L13: 5684.5 | O13: 41579 | P13: 7066.4048 | Q13: -0.017023445 | R13: 16235.772 | S13: 0.032781659
A14: 17 | B14: 5771.5 | C14: 15 | D14: 6016 | E14: 15 | F14: 5850 | G14: 19 | H14: 5600.5 | I14: 16 | J14: 5584 | K14: 15 | L14: 5637 | O14: 41609 | P14: 7202.95 | Q14: 0.019323156 | R14: 16911.086 | S14: 0.041594231
A15: 18 | B15: 5721 | C15: 16 | D15: 6015 | E15: 16 | F15: 5911 | G15: 20 | H15: 5611.5 | I15: 17 | J15: 5575 | K15: 16 | L15: 5655.5 | O15: 41640 | P15: 7294.8864 | Q15: 0.01276371 | R15: 17368.395 | S15: 0.027041961 | T15: 0.027041961
A16: 19 | B16: 5710 | C16: 17 | D16: 5939 | E16: 17 | F16: 5889 | G16: 21 | H16: 5601 | I16: 18 | J16: 5490 | K16: 19 | L16: 5687 | O16: 41671 | P16: 7152.15 | Q16: -0.019566633 | R16: 17062.884 | S16: -0.017590036 | T16: 0.0089762565
A17: 20 | B17: 5706 | C17: 20 | D17: 6002 | E17: 20 | F17: 5891 | G17: 24 | H17: 5612 | I17: 19 | J17: 5596 | K17: 20 | L17: 5673.5 | O17: 41699 | P17: 6667.8095 | Q17: -0.067719564 | R17: 15507.991 | S17: -0.0911272 | T17: -0.082968925
A18: 23 | B18: 5775 | C18: 21 | D18: 6034 | E18: 21 | F18: 5765.5 | G18: 25 | H18: 5652.5 | I18: 22 | J18: 5677 | K18: 21 | L18: 5650 | O18: 41730 | P18: 6670.825 | Q18: 0.0004522439 | R18: 14896.619 | S18: -0.039423035 | T18: -0.11912107
A19: 24 | B19: 5879 | C19: 22 | D19: 5976 | E19: 22 | F19: 5712 | G19: 26 | H19: 5677.5 | I19: 23 | J19: 5660.5 | K19: 22 | L19: 5736 | O19: 41760 | P19: 6883.875 | Q19: 0.031937579 | R19: 15289.775 | S19: 0.02639226 | T19: -0.095872687
A20: 25 | B20: 5867 | C20: 23 | D20: 5991 | E20: 23 | F20: 5790.5 | G20: 27 | H20: 5686.5 | I20: 24 | J20: 5662.5 | K20: 23 | L20: 5774 | O20: 41791 | P20: 6806.0952 | Q20: -0.011298834 | R20: 15206.178 | S20: -0.0054674959 | T20: -0.100816
A21: 26 | B21: 5890 | C21: 24 | D21: 5881 | E21: 24 | F21: 5782.5 | G21: 28 | H21: 5688.5 | I21: 25 | J21: 5665 | K21: 26 | L21: 5771 | O21: 41821 | P21: 7104.8478 | Q21: 0.043894859 | R21: 15807.576 | S21: 0.03954958 | T21: -0.06525365
A22: 27 | B22: 5847 | C22: 27 | D22: 5927 | E22: 27 | F22: 5673.5 | I22: 26 | J22: 5671 | K22: 27 | L22: 5789 | O22: 41852 | P22: 7000.55 | Q22: -0.014679811 | R22: 15880.048 | S22: 0.0045846177 | T22: -0.060968195
A23: 30 | B23: 5857 | C23: 28 | D23: 5936 | E23: 28 | F23: 5774.5 | I23: 30 | J23: 5608 | K23: 28 | L23: 5822 | O23: 41883 | P23: 6872.2273 | Q23: -0.018330378 | R23: 16046.651 | S23: 0.010491345 | T23: -0.051116488
A24: 31 | B24: 5921 | E24: 29 | F24: 5847 | I24: 31 | J24: 5615.5 | K24: 29 | L24: 5905.5 | O24: 41913 | P24: 6739.1957 | Q24: -0.019357861 | R24: 16515.747 | S24: 0.029233272 | T24: -0.023377518
E25: 30 | F25: 5860 | K25: 30 | L25: 5907.5
E26: 31 | F26: 5849 | O26: 41944 | P26: 6701.135 | Q26: -0.005647655 | R26: 17154.906 | S26: 0.038699965 | T26: 0.014417737
A27: =B28/'2016'!L80-1 -> 0.0073564996 | C27: =D28/B28-1 -> 0.035577162 | E27: =F28/D28-1 -> -0.020201506 | G27: =H28/F28-1 -> -0.021275377 | I27: =J28/H28-1 -> -0.018633359 | K27: =L28/J28-1 -> 0.019310967 | O27: 41974 | P27: 6422.9524 | Q27: -0.041512762 | R27: 16968.798 | S27: -0.010848658 | T27: 0.0034126658
A28: MM | B28: =AVERAGE(B4:B26) -> 5737.4286 | C28: MM | D28: =AVERAGE(D4:D24) -> 5941.55 | E28: MM | F28: =AVERAGE(F4:F26) -> 5821.5217 | G28: MM | H28: =AVERAGE(H4:H21) -> 5697.6667 | I28: MM | J28: =AVERAGE(J4:J24) -> 5591.5 | K28: MM | L28: =AVERAGE(L4:L26) -> 5699.4773 | O28: 42005 | P28: 5791.175 | Q28: -0.098362458 | R28: 15271.908 | S28: -0.10000062 | T28: -0.10000062
A29: MM R$ | B29: =B28*A30 -> 18359.771 | C29: MM R$ | D29: =D28*C30 -> 18478.22 | E29: MM R$ | F29: =F28*E30 -> 18191.673 | G29: MM R$ | H29: =H28*G30 -> 17859.336 | I29: MM R$ | J29: =J28*I30 -> 17934.736 | K29: MM R$ | L29: =L28*K30 -> 18764.389 | O29: 42036 | P29: 5702.075 | Q29: -0.015385479 | R29: 16059.837 | S29: 0.051593399 | T29: -0.053566592
A30: 3.2 | B30: =B29/'2016'!L82-1 -> -0.049103009 | C30: 3.11 | D30: =D29/B29-1 -> 0.0064515548 | E30: 3.1249 | F30: =F29/D29-1 -> -0.015507295 | G30: 3.1345 | H30: =H29/F29-1 -> -0.018268639 | I30: 3.2075 | J30: =J29/H29-1 -> 0.0042218861 | K30: 3.2923 | L30: =L29/J29-1 -> 0.046259547 | O30: 42064 | P30: 5919.9048 | Q30: 0.038201841 | R30: 18601.525 | S30: 0.15826359 | T30: 0.096219358
A31: Cobre LME Prices 2017 US$/Ton | O31: MÉDIAS
A32: Julho 2017 | C32: Agosto 2017 | E32: Setembro 2017 | G32: Outubro 2017 | I32: Novembro 2017 | K32: Dezembro 2017 | O32: 42125 | P32: 6300.6053 | Q32: 0.04514038 | R32: 19242.048 | S32: 0.045653962 | T32: 0.13396651
B33: Cash | D33: Cash | F33: Cash | H33: Cash | J33: Cash | L33: Cash | O33: 42156 | P33: 5833.6136 | Q33: -0.074118534 | R33: 18168.79 | S33: -0.055776744 | T33: 0.070717548
A34: Média | B34: #DIV/0! | C34: Média | D34: #DIV/0! | E34: Média | F34: #DIV/0! | G34: Média | H34: #DIV/0! | I34: Média | J34: #DIV/0! | K34: Média | L34: #DIV/0! | O34: 42675 | T34: #DIV/0!
A35: MM | B35: #DIV/0! | C35: MM | D35: #DIV/0! | E35: MM | F35: #DIV/0! | G35: MM | H35: #DIV/0! | I35: MM | J35: #DIV/0! | K35: MM | L35: #DIV/0! | O35: 42705 | T35: #DIV/0!
A36: #DIV/0! | C36: #DIV/0! | E36: #DIV/0! | G36: #DIV/0! | I36: #DIV/0! | K36: #DIV/0! | O36: 42736 | T36: #DIV/0!
A37: MM R$ | B37: #DIV/0! | C37: MM R$ | D37: #DIV/0! | E37: MM R$ | F37: #DIV/0! | G37: MM R$ | H37: #DIV/0! | I37: MM R$ | J37: #DIV/0! | K37: MM R$ | L37: #DIV/0! | O37: 42767 | T37: #DIV/0!
B38: #DIV/0! | D38: #DIV/0! | F38: #DIV/0! | H38: #DIV/0! | J38: #DIV/0! | L38: #DIV/0! | O38: 42795 | T38: #DIV/0!
A39: Julho 2016 | C39: Agosto 2016 | E39: Setembro 2016 | G39: Outubro 2016 | I39: Novembro 2016 | K39: Dezembro 2016 | O39: 42826 | T39: #DIV/0!
B40: Cash | D40: Cash | F40: Cash | H40: Cash | J40: Cash | L40: Cash | O40: 42856 | T40: #DIV/0!
...

Sheet Cotação Média LME

Sheet Dolar Medio
B1: Ano 2013 | C1: Ano 2014 | D1: Ano 2015 | E1: Ano 2016
A2: Janeiro | B2: ='2013'!A31 -> 2.0331 | C2: ='2014'!A31 -> 2.3809 | D2: ='2015'!A31 -> 2.6371 | E2: ='2016'!A29 -> 4.0395
A3: Fevereiro | B3: ='2013'!C31 -> 1.9717 | C3: ='2014'!C31 -> 2.3857 | D3: ='2015'!$C$31 -> 2.81649 | E3: ='2016'!C29 -> 3.9676
A4: Março | B4: ='2013'!E31 -> 1.9854 | C4: ='2014'!E31 -> 2.3258 | D4: ='2015'!$E$31 -> 3.1422 | E4: ='2016'!E29 -> 3.6933
A5: Abril | B5: ='2013'!G31 -> 2.001 | C5: ='2014'!G31 -> 2.2331 | D5: ='2015'!$G$31 -> 3.0525 | E5: ='2016'!G29 -> 3.5659 | M5: Ano 2015 | N5: =D13/C13-1 -> 0.46595253
A6: Maio | B6: ='2013'!I31 -> 2.034 | C6: ='2014'!I31 -> 2.2211 | D6: ='2015'!I31 -> 3.054 | E6: 3.54
A7: Junho | B7: ='2013'!K31 -> 2.17 | C7: ='2014'!K31 -> 2.2342 | D7: ='2015'!K31 -> 3.1145 | E7: ='2016'!K29 -> 3.43 | M7: Ano 2016 | N7: =E11/D13-1 -> -0.17622453
A8: Julho | B8: ='2013'!A62 -> 2.25268 | C8: ='2014'!A85 -> 2.2249 | D8: ='2015'!A85 -> 3.2188 | E8: 3.27
A9: Agosto | B9: ='2013'!C62 -> 2.3395 | C9: ='2014'!C85 -> 2.2684 | D9: ='2015'!$C$85 -> 3.5069 | E9: 3.29
A10: Setembro | B10: ='2013'!E62 -> 2.2711 | C10: ='2014'!E85 -> 2.335 | D10: ='2015'!E85 -> 3.8957 | E10: ='2016'!E83 -> 3.2564
A11: Outubro | B11: ='2013'!G62 -> 2.1868 | C11: ='2014'!G85 -> 2.4507 | D11: ='2015'!G85 -> 3.8724 | E11: ='2016'!G83 -> 3.1904
A12: Novembro | B12: ='2013'!I62 -> 2.2976 | C12: ='2014'!I85 -> 2.56 | D12: ='2015'!I85 -> 3.7782 | E12: ='2016'!I83 -> 3.33
A13: Dezembro | B13: ='2013'!$K$62 -> 2.3478 | C13: ='2014'!K85 -> 2.6419 | D13: ='2015'!K85 -> 3.8729
C14: =C13/B13-1 -> 0.12526621 | D14: =D13/C13-1 -> 0.46595253 | E14: =E12/D13-1 -> -0.14017919
A88: Mês | B88: Valor
A89: 41275 | B89: 2.0331
A90: 41306 | B90: 1.9717
A91: 41334 | B91: 1.9854
A92: 41365 | B92: 2.001
A93: 41395 | B93: 2.034
A94: 41426 | B94: 2.17
A95: 41456 | B95: 2.25268
A96: 41487 | B96: 2.3395
A97: 41518 | B97: 2.2711
A98: 41548 | B98: 2.1868
A99: 41579 | B99: 2.2976
A100: 41609 | B100: 2.3478
... A133: 42614 | B133: 3.27

Sheet LME Média
A1: MÉDIAS
C2: US$ | D2: Var (%) | E2: R$ | F2: Var (%)
A3: 41275 | C3: 8049.2455 | D3: =C3/7962.58-1 -> 0.010884092 | E3: 16364.921 | F3: =E3/16546.24-1 -> -0.010958324
A4: 41306 | C4: 8070.475 | D4: =C4/C3-1 -> 0.0026374578 | E4: 15912.556 | F4: =E4/E3-1 -> -0.027642381
A5: 41334 | C5: 7662.4 | D5: =C5/C4-1 -> -0.050563938 | E5: 15212.929 | F5: =E5/E4-1 -> -0.043966954
A6: 41365 | C6: 7203.3571 | D6: =C6/C5-1 -> -0.059908496 | E6: 14413.918 | F6: =E6/E5-1 -> -0.052521859
A7: 41395 | C7: 7229.1429 | D7: =C7/C6-1 -> 0.0035796801 | E7: 14704.077 | F7: =E7/E6-1 -> 0.020130469
A8: 41426 | C8: 7004.05 | D8: =C8/C7-1 -> -0.031136867 | E8: 15198.789 | F8: =E8/E7-1 -> 0.033644542
A9: 41456 | C9: 6896.9773 | D9: =C9/C8-1 -> -0.015287259 | E9: 15536.683 | F9: =E9/E8-1 -> 0.022231658
A10: 41487 | C10: 7182.2619 | D10: =C10/C9-1 -> 0.041363719 | E10: 16802.902 | F10: =E10/E9-1 -> 0.081498669
A11: 41518 | C11: 7161.4286 | D11: =C11/C10-1 -> -0.0029006647 | E11: 16264.32 | F11: =E11/E10-1 -> -0.032052874
A12: 41548 | C12: 7188.7826 | D12: =C12/C11-1 -> 0.0038196342 | E12: 15720.43 | F12: =E12/E11-1 -> -0.033440722
A13: 41579 | C13: 7066.4048 | D13: =C13/C12-1 -> -0.017023445 | E13: 16235.772 | F13: =E13/E12-1 -> 0.032781659
A14: 41609 | C14: 7202.95 | D14: =C14/C13-1 -> 0.019323156 | E14: 16911.086 | F14: =E14/E13-1 -> 0.041594231
A15: 41640 | C15: ='2014'!B28 -> 7294.8864 | D15: =C15/C14-1 -> 0.01276371 | E15: ='2014'!B30 -> 17368.395 | F15: =E15/E14-1 -> 0.027041961
A16: 41671 | C16: ='2014'!D28 -> 7152.15 | D16: =C16/C15-1 -> -0.019566633 | E16: ='2014'!D30 -> 17062.884 | F16: =E16/E15-1 -> -0.017590036
A17: 41699 | C17: ='2014'!P17 -> 6667.8095 | D17: =C17/C16-1 -> -0.067719564 | E17: ='2014'!R17 -> 15507.991 | F17: =E17/E16-1 -> -0.0911272
A18: 41730 | C18: ='2014'!$P$18 -> 6670.825 | D18: =C18/C17-1 -> 0.0004522439 | E18: ='2014'!$R$18 -> 14896.619 | F18: =E18/E17-1 -> -0.039423035
A19: 41760 | C19: ='2015'!$P$19 -> 6883.875 | D19: =C19/C18-1 -> 0.031937579 | E19: ='2015'!$R$19 -> 15289.775 | F19: =E19/E18-1 -> 0.02639226
A20: 41791 | C20: ='2015'!$P$20 -> 6806.0952 | D20: =C20/C19-1 -> -0.011298834 | E20: ='2015'!$R$20 -> 15206.178 | F20: =E20/E19-1 -> -0.0054674959
A21: 41821 | C21: ='2015'!$P$21 -> 7104.8478 | D21: =C21/C20-1 -> 0.043894859 | E21: ='2015'!$R$21 -> 15807.576 | F21: =E21/E20-1 -> 0.03954958
A22: 41852 | C22: ='2015'!$P$22 -> 7000.55 | D22: =C22/C21-1 -> -0.014679811 | E22: ='2015'!R22 -> 15880.048 | F22: =E22/E21-1 -> 0.0045846177
A23: 41883 | C23: ='2015'!$P$23 -> 6872.2273 | D23: =C23/C22-1 -> -0.018330378 | E23: ='2015'!R23 -> 16046.651 | F23: =E23/E22-1 -> 0.010491345
A24: 41913 | C24: ='2015'!$P$24 -> 6739.1957 | D24: =C24/C23-1 -> -0.019357861 | E24: ='2015'!R24 -> 16515.747 | F24: =E24/E23-1 -> 0.029233272
A25: 41944 | C25: ='2015'!$P$25 -> 6701.135 | D25: =C25/C24-1 -> -0.005647655 | E25: ='2015'!R25 -> 17154.906 | F25: =E25/E24-1 -> 0.038699965
A26: 41974 | C26: ='2015'!$P$26 -> 6422.9524 | D26: =C26/C25-1 -> -0.041512762 | E26: ='2015'!R26 -> 16968.798 | F26: =E26/E25-1 -> -0.010848658
A27: 42005 | C27: ='2015'!$P$27 -> 5791.175 | D27: =C27/C26-1 -> -0.098362458 | E27: ='2015'!R27 -> 15271.908 | F27: =E27/E26-1 -> -0.10000062
A28: 42036 | C28: ='2015'!$P$28 -> 5702.075 | D28: =C28/C27-1 -> -0.015385479 | E28: ='2015'!R28 -> 16059.837 | F28: =E28/E27-1 -> 0.051593399
A29: 42064 | C29: ='2015'!$P$29 -> 5919.9048 | D29: =C29/C28-1 -> 0.038201841 | E29: ='2015'!R29 -> 18601.525 | F29: =E29/E28-1 -> 0.15826359
A30: 42095 | C30: ='2015'!$P$30 -> 6028.4775 | D30: =C30/C29-1 -> 0.018340285 | E30: ='2015'!R30 -> 18401.928 | F30: =E30/E29-1 -> -0.010730151
A31: 42125 | C31: ='2015'!$P$31 -> 6300.6053 | D31: =C31/C30-1 -> 0.04514038 | E31: ='2015'!R31 -> 19242.048 | F31: =E31/E30-1 -> 0.045653962
A32: 42156 | C32: ='2015'!$P$32 -> 5833.6136 | D32: =C32/C31-1 -> -0.074118534 | E32: ='2015'!R32 -> 18168.79 | F32: =E32/E31-1 -> -0.055776744
A33: 42186 | C33: ='2015'!$P$56 -> 5456.913 | D33: =C33/C32-1 -> -0.064574142 | E33: ='2015'!R56 -> 17564.712 | F33: =E33/E32-1 -> -0.033248113
A34: 42217 | C34: ='2015'!$P$57 -> 5088.925 | D34: =C34/C33-1 -> -0.067435204 | E34: ='2015'!R57 -> 17846.351 | F34: =E34/E33-1 -> 0.016034387
A35: 42248 | C35: ='2015'!P58 -> 5208.0909 | D35: =C35/C34-1 -> 0.023416716 | E35: ='2015'!R58 -> 20289.16 | F35: =E35/E34-1 -> 0.13688001
A36: 42278 | C36: ='2015'!P59 -> 5222.6136 | D36: =C36/C35-1 -> 0.0027884934 | E36: ='2015'!R59 -> 20224.049 | F36: =E36/E35-1 -> -0.0032091378
A37: 42309 | C37: ='2015'!P60 -> 4808.2381 | D37: =C37/C36-1 -> -0.079342561 | E37: ='2015'!R60 -> 18166.485 | F37: =E37/E36-1 -> -0.10173847
A38: 42339 | C38: ='2015'!L82 -> 4629 | D38: =C38/C37-1 -> -0.037277292 | E38: ='2015'!L84 -> 17927.654 | F38: =E38/E37-1 -> -0.013146796
A39: 42370 | C39: ='2016'!B27 -> 4462.75 | D39: =C39/C38-1 -> -0.035914884 | E39: ='2016'!B28 -> 18027.279 | F39: =E39/E38-1 -> 0.0055570307
A40: 42401 | C40: ='2016'!D27 -> 4595.4762 | D40: =C40/C39-1 -> 0.029740898 | E40: ='2016'!D28 -> 18233.011 | F40: =E40/E39-1 -> 0.0114123
...

Sheet Cotação Dolar
A1: Data | B1: Valor
A2: 42583 | B2: 3.2662
A3: 42584 | B3: 3.249
A4: 42585 | B4: 3.2733
A5: 42586 | B5: 3.2183
A6: 42587 | B6: 3.1859
A7: 42590 | B7: 3.1771
A8: 42591 | B8: 3.1503
A9: 42592 | B9: 3.1302
A10: 42593 | B10: 3.1364
A11: 42594 | B11: 3.1602
A12: 42597 | B12: 3.1672
A13: 42598 | B13: 3.1749
... A24: 42613 | B24: 3.2403
A25: Média Mensal | B25: =AVERAGE(B2:B24) -> 3.2096609
A27: 42614 | B27: 3.2472
A28: 42615 | B28: 3.2431
A29: 42618 | B29: 3.2721
A30: 42619 | B30: 3.2452
A31: 42620 | B31: 3.2452
A32: 42621 | B32: 3.1934
A33: 42622 | B33: 3.2638
A34: 42625 | B34: 3.2854
A35: 42626 | B35: 3.2972
A36: 42627 | B36: 3.3262
A37: 42628 | B37: 3.3326
A38: 42629 | B38: 3.3004
... A48: 42643 | B48: 3.2462
A49: Média Mensal | B49: =AVERAGE(B27:B48) -> 3.2558636
A51: 42646 | B51: 3.2338
A52: 42647 | B52: 3.2203
A53: 42648 | B53: 3.2359
A54: 42648 | B54: 3.2203
A55: 42649 | B55: 3.2359
A56: 42650 | B56: 3.231
A57: 42653 | B57: 3.2134
A58: 42654 | B58: 3.2125
A59: 42655 | B59: feriado
A60: 42656 | B60: 3.2136
A61: 42657 | B61: 3.2087
...

Sheet 2018
A1: Cobre LME Prices 2018 US$/Ton | O1: MÉDIAS
A2: Janeiro 2018 | C2: Fevereiro 2018 | E2: Março 2018 | G2: Abril 2018 | I2: Maio 2018 | K2: Junho 2018 | P2: US$ | Q2: Var (%) | R2: R$ | S2: Var Mês (%) | T2: Acumulado/Ano
B3: Cash | D3: Cash | F3: Cash | H3: Cash | J3: Cash | L3: Cash | O3: 41275 | P3: 8049.2455 | Q3: 0.010884092 | R3: 16364.921 | S3: -0.010958324
A4: 2 | B4: 7181 | C4: 1 | D4: 7027 | E4: 1 | F4: 6852 | G4: 3 | H4: 6756 | I4: 1 | J4: 6777.5 | K4: 1 | L4: 6814 | O4: 41306 | P4: 8070.475 | Q4: 0.0026374578 | R4: 15912.556 | S4: -0.027642381
A5: 3 | B5: 7115.5 | C5: 2 | D5: 7066 | E5: 2 | F5: 6883 | G5: 4 | H5: 6625 | I5: 2 | J5: 6785 | K5: 4 | L5: 6935 | O5: 41334 | P5: 7662.4 | Q5: -0.050563938 | R5: 15212.929 | S5: -0.043966954
A6: 4 | B6: 7202.5 | C6: 5 | D6: 7050 | E6: 5 | F6: 6850 | G6: 5 | H6: 6767 | I6: 3 | J6: 6837 | K6: 5 | L6: 6971 | O6: 41365 | P6: 7203.3571 | Q6: -0.059908496 | R6: 14413.918 | S6: -0.052521859
A7: 5 | B7: 7097 | C7: 6 | D7: 7060 | E7: 6 | F7: 6968.5 | G7: 6 | H7: 6703 | I7: 4 | J7: 6783 | K7: 6 | L7: 7147 | O7: 41395 | P7: 7229.1429 | Q7: 0.0035796801 | R7: 14704.077 | S7: 0.020130469
A8: 8 | B8: 7084.5 | C8: 7 | D8: 7006 | E8: 7 | F8: 6873 | G8: 9 | H8: 6767 | I8: 8 | J8: 6722 | K8: 7 | L8: 7245.5 | O8: 41426 | P8: 7004.05 | Q8: -0.031136867 | R8: 15198.789 | S8: 0.033644542
A9: 9 | B9: 7092 | C9: 8 | D9: 6838 | E9: 8 | F9: 6830 | G9: 10 | H9: 6888 | I9: 9 | J9: 6786 | K9: 8 | L9: 7262.5 | N9: =L8/B25 -> 1.0204211 | O9: 41456 | P9: 6896.9773 | Q9: -0.015287259 | R9: 15536.683 | S9: 0.022231658
A10: 10 | B10: 7140.5 | C10: 9 | D10: 6755 | E10: 9 | F10: 6808 | G10: 11 | H10: 6930.5 | I10: 10 | J10: 6862 | K10: 11 | L10: 7223.5 | O10: 41487 | P10: 7182.2619 | Q10: 0.041363719 | R10: 16802.902 | S10: 0.081498669
A11: 11 | B11: 7123 | C11: 12 | D11: 6786.5 | E11: 12 | F11: 6857 | G11: 12 | H11: 6756 | I11: 11 | J11: 6869 | K11: 12 | L11: 7200.5 | O11: 41518 | P11: 7161.4286 | Q11: -0.0029006647 | R11: 16264.32 | S11: -0.032052874
A12: 12 | B12: 7070.5 | C12: 13 | D12: 6908 | E12: 13 | F12: 6883 | G12: 13 | H12: 6830 | I12: 14 | J12: 6828 | K12: 13 | L12: 7201.5 | O12: 41548 | P12: 7188.7826 | Q12: 0.0038196342 | R12: 15720.43 | S12: -0.033440722
A13: 15 | B13: 7180 | C13: 14 | D13: 6962 | E13: 14 | F13: 7015 | G13: 16 | H13: 6811.5 | I13: 15 | J13: 6822.5 | K13: 14 | L13: 7197 | O13: 41579 | P13: 7066.4048 | Q13: -0.017023445 | R13: 16235.772 | S13: 0.032781659
A14: 16 | B14: 7023 | C14: 15 | D14: 7098 | E14: 15 | F14: 6885.5 | G14: 17 | H14: 6784 | I14: 16 | J14: 6773.5 | K14: 15 | L14: 7136 | O14: 41609 | P14: 7202.95 | Q14: 0.019323156 | R14: 16911.086 | S14: 0.041594231
A15: 17 | B15: 7047 | C15: 16 | D15: 7159 | E15: 16 | F15: 6923 | G15: 18 | H15: 6936 | I15: 17 | J15: 6838 | K15: 18 | L15: 6987 | O15: 41640 | P15: 7294.8864 | Q15: 0.01276371 | R15: 17368.395 | S15: 0.027041961 | T15: 0.027041961
A16: 18 | B16: 7047 | C16: 19 | D16: 7093 | E16: 19 | F16: 6791.5 | G16: 19 | H16: 6942 | I16: 18 | J16: 6783.5 | K16: 19 | L16: 6820 | O16: 41671 | P16: 7152.15 | Q16: -0.019566633 | R16: 17062.884 | S16: -0.017590036 | T16: 0.0089762565
A17: 19 | B17: 7079 | C17: 20 | D17: 7027 | E17: 20 | F17: 6784 | G17: 20 | H17: 6939 | I17: 21 | J17: 6861 | K17: 20 | L17: 6819 | O17: 41699 | P17: 6667.8095 | Q17: -0.067719564 | R17: 15507.991 | S17: -0.0911272 | T17: -0.082968925
A18: 22 | B18: 7049 | C18: 21 | D18: 7003 | E18: 21 | F18: 6675 | G18: 23 | H18: 6923 | I18: 22 | J18: 6931.5 | K18: 21 | L18: 6801 | O18: 41730 | P18: 6670.825 | Q18: 0.0004522439 | R18: 14896.619 | S18: -0.039423035 | T18: -0.11912107
A19: 23 | B19: 6905 | C19: 22 | D19: 7032 | E19: 22 | F19: 6746.5 | G19: 24 | H19: 6987 | I19: 23 | J19: 6800 | K19: 22 | L19: 6811 | O19: 41760 | P19: 6883.875 | Q19: 0.031937579 | R19: 15289.775 | S19: 0.02639226 | T19: -0.095872687
A20: 24 | B20: 6943 | C20: 23 | D20: 7073.5 | E20: 23 | F20: 6658 | G20: 25 | H20: 6960.5 | I20: 24 | J20: 6835 | K20: 25 | L20: 6783 | O20: 41791 | P20: 6806.0952 | Q20: -0.011298834 | R20: 15206.178 | S20: -0.0054674959 | T20: -0.100816
A21: 25 | B21: 7112 | C21: 26 | D21: 7111 | E21: 26 | F21: 6500 | G21: 26 | H21: 6885.5 | I21: 25 | J21: 6886 | K21: 26 | L21: 6712 | O21: 41821 | P21: 7104.8478 | Q21: 0.043894859 | R21: 15807.576 | S21: 0.03954958 | T21: -0.06525365
A22: 26 | B22: 7063.5 | C22: 27 | D22: 7028 | E22: 27 | F22: 6641.5 | G22: 27 | H22: 6797 | I22: 29 | J22: 6840.5 | K22: 27 | L22: 6688 | O22: 41852 | P22: 7000.55 | Q22: -0.014679811 | R22: 15880.048 | S22: 0.0045846177 | T22: -0.060968195
A23: 29 | B23: 7062 | C23: 28 | D23: 6953 | E23: 28 | F23: 6601.5 | G23: 30 | H23: 6783 | I23: 30 | J23: 6810 | K23: 28 | L23: 6650 | O23: 41883 | P23: 6872.2273 | Q23: -0.018330378 | R23: 16046.651 | S23: 0.010491345 | T23: -0.051116488
A24: 30 | B24: 7049 | E24: 29 | F24: 6685 | I24: 31 | J24: 6825 | K24: 29 | L24: 6646 | O24: 41913 | P24: 6739.1957 | Q24: -0.019357861 | R24: 16515.747 | S24: 0.029233272 | T24: -0.023377518
A25: 31 | B25: 7100.5 | E25: 30
O26: 41944 | P26: 6701.135 | Q26: -0.005647655 | R26: 17154.906 | S26: 0.038699965 | T26: 0.014417737
A27: =B28/'2017'!L65-1 -> 0.041042652 | C27: =D28/B28-1 -> -0.011086466 | E27: =F28/D28-1 -> -0.029426447 | G27: =H28/F28-1 -> 0.0062962911 | I27: =J28/H28-1 -> -0.0024618836 | K27: =L28/J28-1 -> 0.019507036 | O27: 41974 | P27: 6422.9524 | Q27: -0.041512762 | R27: 16968.798 | S27: -0.010848658 | T27: 0.0034126658
A28: MM | B28: =AVERAGE(B4:B25) -> 7080.2955 | C28: MM | D28: =AVERAGE(D4:D23) -> 7001.8 | E28: MM | F28: =AVERAGE(F4:F25) -> 6795.7619 | G28: MM | H28: =AVERAGE(H4:H24) -> 6838.55 | I28: MM | J28: =AVERAGE(J4:J25) -> 6821.7143 | K28: MM | L28: =AVERAGE(L4:L24) -> 6954.7857 | O28: 42005 | P28: 5791.175 | Q28: -0.098362458 | R28: 15271.908 | S28: -0.10000062 | T28: -0.10000062
A29: MM R$ | B29: =B28*A30 -> 22736.245 | C29: MM R$ | D29: =D28*C30 -> 22711.038 | E29: MM R$ | F29: =F28*E30 -> 22341.747 | G29: MM R$ | H29: =H28*G30 -> 23302.359 | I29: MM R$ | J29: =J28*I30 -> 24721.21 | K29: MM R$ | L29: =L28*K30 -> 26117.307 | O29: 42036 | P29: 5702.075 | Q29: -0.015385479 | R29: 16059.837 | S29: 0.051593399 | T29: -0.053566592
A30: 3.2112 | B30: =B29/'2017'!L67-1 -> 0.014597155 | C30: 3.2436 | D30: =D29/B29-1 -> -0.0011086388 | E30: 3.2876 | F30: =F29/D29-1 -> -0.016260447 | G30: 3.4075 | H30: =H29/F29-1 -> 0.042996293 | I30: 3.6239 | J30: =J29/H29-1 -> 0.06088874 | K30: 3.7553 | L30: =L29/J29-1 -> 0.056473626 | O30: 42064 | P30: 5919.9048 | Q30: 0.038201841 | R30: 18601.525 | S30: 0.15826359 | T30: 0.096219358
A31: Cobre LME Prices 2018 US$/Ton | O31: MÉDIAS
A32: Julho 2018 | C32: Agosto 2018 | E32: Setembro 2018 | G32: Outubro 2018 | I32: Novembro 2018 | K32: Dezembro 2018 | O32: 42125 | P32: 6300.6053 | Q32: 0.04514038 | R32: 19242.048 | S32: 0.045653962 | T32: 0.13396651
B33: Cash | D33: Cash | F33: Cash | H33: Cash | J33: Cash | L33: Cash | O33: 42156 | P33: 5833.6136 | Q33: -0.074118534 | R33: 18168.79 | S33: -0.055776744 | T33: 0.070717548
A34: Média | B34: #DIV/0! | C34: Média | D34: #DIV/0! | E34: Média | F34: #DIV/0! | G34: Média | H34: #DIV/0! | I34: Média | J34: #DIV/0! | K34: Média | L34: #DIV/0! | O34: 42675 | T34: #DIV/0!
A35: MM | B35: #DIV/0! | C35: MM | D35: #DIV/0! | E35: MM | F35: #DIV/0! | G35: MM | H35: #DIV/0! | I35: MM | J35: #DIV/0! | K35: MM | L35: #DIV/0! | O35: 42705 | T35: #DIV/0!
A36: #DIV/0! | C36: #DIV/0! | E36: #DIV/0! | G36: #DIV/0! | I36: #DIV/0! | K36: #DIV/0! | O36: 42736 | T36: #DIV/0!
A37: MM R$ | B37: #DIV/0! | C37: MM R$ | D37: #DIV/0! | E37: MM R$ | F37: #DIV/0! | G37: MM R$ | H37: #DIV/0! | I37: MM R$ | J37: #DIV/0! | K37: MM R$ | L37: #DIV/0! | O37: 42767 | T37: #DIV/0!
B38: #DIV/0! | D38: #DIV/0! | F38: #DIV/0! | H38: #DIV/0! | J38: #DIV/0! | L38: #DIV/0! | O38: 42795 | T38: #DIV/0!
A39: Julho 2016 | C39: Agosto 2016 | E39: Setembro 2016 | G39: Outubro 2016 | I39: Novembro 2016 | K39: Dezembro 2016 | O39: 42826 | T39: #DIV/0!
B40: Cash | D40: Cash | F40: Cash | H40: Cash | J40: Cash | L40: Cash | O40: 42856 | T40: #DIV/0!
...

Sheet 2019
A1: Cobre LME Prices 2019 US$/Ton | O1: MÉDIAS
A2: Janeiro 2019 | C2: Fevereiro 2019 | E2: Março 2019 | G2: Abril 2019 | I2: Maio 2019 | K2: Junho 2019 | P2: US$ | Q2: Var (%) | R2: R$ | S2: Var Mês (%) | T2: Acumulado/Ano
B3: Cash | D3: Cash | F3: Cash | H3: Cash | J3: Cash | L3: Cash | O3: 41275 | P3: 8049.2455 | Q3: 0.010884092 | R3: 16364.921 | S3: -0.010958324
A4: 2 | B4: 5839 | C4: 1 | D4: 6097.5 | E4: 1 | F4: 6572 | G4: 1 | H4: 6498 | I4: 1 | J4: 6398 | K4: 3 | L4: 5796 | O4: 41306 | P4: 8070.475 | Q4: 0.0026374578 | R4: 15912.556 | S4: -0.027642381
A5: 3 | B5: 5811 | C5: 4 | D5: 6076.5 | E5: 2 | F5: 6420 | G5: 2 | H5: 6431 | I5: 2 | J5: 6214 | K5: 4 | L5: 5804 | O5: 41334 | P5: 7662.4 | Q5: -0.050563938 | R5: 15212.929 | S5: -0.043966954
A6: 4 | B6: 5840 | C6: 5 | D6: 6174 | E6: 5 | F6: 6553.5 | G6: 3 | H6: 6483 | I6: 3 | J6: 6180 | K6: 5 | L6: 5832.5 | O6: 41365 | P6: 7203.3571 | Q6: -0.059908496 | R6: 14413.918 | S6: -0.052521859
A7: 7 | B7: 5889.5 | C7: 6 | D7: 6210 | E7: 6 | F7: 6505 | G7: 4 | H7: 6444 | I7: 7 | J7: 6174 | K7: 6 | L7: 5805 | O7: 41395 | P7: 7229.1429 | Q7: 0.0035796801 | R7: 14704.077 | S7: 0.020130469
A8: 8 | B8: 5904.5 | C8: 7 | D8: 6227 | E8: 7 | F8: 6458 | G8: 5 | H8: 6419 | I8: 8 | J8: 6103 | K8: 7 | L8: 5770 | O8: 41426 | P8: 7004.05 | Q8: -0.031136867 | R8: 15198.789 | S8: 0.033644542
A9: 9 | B9: 5964 | C9: 8 | D9: 6207 | E9: 8 | F9: 6398.5 | G9: 8 | H9: 6432.5 | I9: 9 | J9: 6112 | K9: 10 | L9: 5788 | O9: 41456 | P9: 6896.9773 | Q9: -0.015287259 | R9: 15536.683 | S9: 0.022231658
A10: 10 | B10: 5908.5 | C10: 11 | D10: 6148 | E10: 11 | F10: 6435 | G10: 9 | H10: 6498 | I10: 10 | J10: 6135.5 | K10: 11 | L10: 5905 | O10: 41487 | P10: 7182.2619 | Q10: 0.041363719 | R10: 16802.902 | S10: 0.081498669
A11: 11 | B11: 5926.5 | C11: 12 | D11: 6102 | E11: 12 | F11: 6510 | G11: 10 | H11: 6447 | I11: 13 | J11: 6042.5 | K11: 12 | L11: 5828.5 | O11: 41518 | P11: 7161.4286 | Q11: -0.0029006647 | R11: 16264.32 | S11: -0.032052874
A12: 14 | B12: 5861 | C12: 13 | D12: 6120 | E12: 13 | F12: 6529 | G12: 11 | H12: 6432.5 | I12: 14 | J12: 6007 | K12: 13 | L12: 5797.5 | O12: 41548 | P12: 7188.7826 | Q12: 0.0038196342 | R12: 15720.43 | S12: -0.033440722
A13: 15 | B13: 5882 | C13: 14 | D13: 6178.5 | E13: 14 | F13: 6409 | G13: 12 | H13: 6490 | I13: 15 | J13: 6002 | K13: 14 | L13: 5805.5 | O13: 41579 | P13: 7066.4048 | Q13: -0.017023445 | R13: 16235.772 | S13: 0.032781659
A14: 16 | B14: 5911 | C14: 15 | D14: 6190 | E14: 15 | F14: 6410 | G14: 15 | H14: 6456 | I14: 16 | J14: 6089 | K14: 17 | L14: 5756 | O14: 41609 | P14: 7202.95 | Q14: 0.019323156 | R14: 16911.086 | S14: 0.041594231
A15: 17 | B15: 5933 | C15: 16 | D15: 6269.5 | E15: 18 | F15: 6492 | G15: 16 | H15: 6460 | I15: 17 | J15: 6025 | K15: 18 | L15: 5848.5 | O15: 41640 | P15: 7294.8864 | Q15: 0.01276371 | R15: 17368.395 | S15: 0.027041961 | T15: 0.027041961
A16: 18 | B16: 6022 | C16: 19 | D16: 6246.5 | E16: 19 | F16: 6500 | G16: 17 | H16: 6509 | I16: 20 | J16: 5985 | K16: 19 | L16: 5895 | O16: 41671 | P16: 7152.15 | Q16: -0.019566633 | R16: 17062.884 | S16: -0.017590036 | T16: 0.0089762565
A17: 21 | B17: 5951.5 | C17: 20 | D17: 6351.5 | E17: 20 | F17: 6487 | G17: 18 | H17: 6448 | I17: 21 | J17: 6004 | K17: 20 | L17: 5962 | O17: 41699 | P17: 6667.8095 | Q17: -0.067719564 | R17: 15507.991 | S17: -0.0911272 | T17: -0.082968925
A18: 22 | B18: 5926.5 | C18: 21 | D18: 6391 | E18: 21 | F18: 6520 | G18: 23 | H18: 6430 | I18: 22 | J18: 5920 | K18: 21 | L18: 5941 | O18: 41730 | P18: 6670.825 | Q18: 0.0004522439 | R18: 14896.619 | S18: -0.039423035 | T18: -0.11912107
A19: 23 | B19: 5920.5 | C19: 22 | D19: 6449 | E19: 22 | F19: 6375 | G19: 24 | H19: 6437.5 | I19: 23 | J19: 5860 | K19: 24 | L19: 5917 | O19: 41760 | P19: 6883.875 | Q19: 0.031937579 | R19: 15289.775 | S19: 0.02639226 | T19: -0.095872687
A20: 24 | B20: 5885 | C20: 25 | D20: 6546 | E20: 25 | F20: 6328 | G20: 25 | H20: 6375.5 | I20: 24 | J20: 5919 | K20: 25 | L20: 5985.5 | O20: 41791 | P20: 6806.0952 | Q20: -0.011298834 | R20: 15206.178 | S20: -0.0054674959 | T20: -0.100816
A21: 25 | B21: 5901 | C21: 26 | D21: 6471 | E21: 26 | F21: 6361 | G21: 26 | H21: 6393 | I21: 28 | J21: 5956.5 | K21: 26 | L21: 6006 | O21: 41821 | P21: 7104.8478 | Q21: 0.043894859 | R21: 15807.576 | S21: 0.03954958 | T21: -0.06525365
A22: 28 | B22: 5996 | C22: 27 | D22: 6533 | E22: 27 | F22: 6338.5 | G22: 27 | H22: 6376 | I22: 29 | J22: 5864.5 | K22: 27 | L22: 5953.5 | O22: 41852 | P22: 7000.55 | Q22: -0.014679811 | R22: 15880.048 | S22: 0.0045846177 | T22: -0.060968195
A23: 29 | B23: 6007 | C23: 28 | D23: 6572 | E23: 28 | F23: 6385 | G23: 30 | H23: 6442 | I23: 30 | J23: 5780.5 | K23: 28 | L23: 5972 | O23: 41883 | P23: 6872.2273 | Q23: -0.018330378 | R23: 16046.651 | S23: 0.010491345 | T23: -0.051116488
A24: 30 | B24: 6077 | E24: 29 | F24: 6485 | I24: 31 | O24: 41913 | P24: 6739.1957 | Q24: -0.019357861 | R24: 16515.747 | S24: 0.029233272 | T24: -0.023377518
A25: 31 | B25: 6148 | E25: 30
O26: 41944 | P26: 6701.135 | Q26: -0.005647655 | R26: 17154.906 | S26: 0.038699965 | T26: 0.014417737
A27: =B28/'2018'!L65-1 -> -0.026613422 | C27: =D28/B28-1 -> 0.058323659 | E27: =F28/D28-1 -> 0.027560339 | G27: =H28/F28-1 -> -0.00091827432 | I27: =J28/H28-1 -> -0.063075049 | K27: =L28/J28-1 -> -0.028177178 | O27: 41974 | P27: 6422.9524 | Q27: -0.041512762 | R27: 16968.798 | S27: -0.010848658 | T27: 0.0034126658
